Workbook

Sheet Inlet coolers (5)
A1: HGF Inlet Cooler (5) Efficiency Calculator
A2: Temperatures (°F) | O2: Date of Assess
A3: Cooler # | B3: IC-1 | D3: IC-2 | F3: IC-3 | H3: AC/IC-4 | J3: EJW | L3: TAW/CLO | O3: 45834
B4: T_in | C4: T_out | D4: T_in | E4: T_out | F4: T_in | G4: T_out | H4: T_in | I4: T_out | J4: T_in | K4: T_out | L4: T_in | M4: T_out
A5: 1 | B5: 226.33333 | C5: 128.5 | D5: 204 | E5: 123.4 | F5: 216 | G5: 123.3 | H5: 220 | I5: 125.2 | J5: 181
A6: 2 | B6: 237 | C6: 117.9 | D6: 199 | E6: 117.4 | F6: 212 | G6: 117.6 | H6: 226 | I6: 116 | J6: 181
A7: 3 | B7: 245 | C7: 108.7 | D7: 195 | E7: 114 | F7: 207 | G7: 112.4 | H7: 219 | I7: 120.3 | J7: 181
A8: 4 | B8: 194 | C8: 117.3 | D8: 210 | E8: 116.8 | F8: 245 | G8: 114.7 | H8: 229 | I8: 116 | J8: 181
A9: 5 | B9: 201 | C9: 102.8 | D9: 203 | E9: 101 | F9: 239 | G9: 105.6 | H9: 233 | I9: 115.9 | J9: 174
A11: Flows (MMCFD) | E11: T Setpoint (°F) & Louver Position (%)
A12: Cooler # | B12: Inlet Gas Today | C12: Total Flow Today | E12: Cooler # | F12: IC-1 | I12: IC-2 | L12: IC-3 | O12: AC/IC-4
A13: 1 | B13: 12.615755 | C13: 12.7289 | F13: T Setpoint | G13: Louver | H13: Actual T | I13: T Setpoint | J13: Louver | K13: Actual T | L13: T Setpoint | M13: Louver | N13: Actual T | O13: T Setpoint | P13: Louver | Q13: Actual T
A14: 2 | B14: 11.893247 | C14: 12.001133 | E14: 1 | F14: 120 | G14: 0.179 | H14: 128.5 | I14: 123.4 | J14: 0.678 | K14: 123.4 | L14: 120 | M14: 0.278 | N14: 123.3 | O14: 120 | P14: 0.275 | Q14: 125.2
A15: 3 | B15: 11.184317 | C15: 11.273828 | E15: 2 | F15: 120 | G15: 0.191 | H15: 117.9 | I15: 120 | J15: 0.075 | K15: 117.4 | L15: 120 | M15: 0.671 | N15: 117.6 | O15: 120 | P15: 0.293 | Q15: 116
A16: 4 | B16: 6.425383 | C16: 6.43422 | E16: 3 | F16: 120 | G16: 0.328 | H16: 108.7 | I16: 120 | J16: 0.12 | K16: 114 | L16: 120 | M16: 0.254 | N16: 112.4 | O16: 120 | P16: 0.433 | Q16: 120.3
A17: 5 | B17: 6.525 | C17: 6.5789 | E17: 4 | F17: 120 | G17: 0.426 | H17: 117.3 | I17: 120 | J17: 0.247 | K17: 116.8 | L17: 120 | M17: 0.572 | N17: 114.7 | O17: 120 | P17: 0.09 | Q17: 116
E18: 5 | F18: 100 | G18: 0.471 | H18: 102.8 | I18: 100 | J18: 0.267 | K18: 101 | L18: 105 | M18: 0.401 | N18: 105.6 | O18: 115 | P18: 0.358 | Q18: 115.9
A20: Actual Duty (1000 BTU/hr)
A21: Cooler # | B21: IC-1 | D21: IC-2 | F21: IC-3 | H21: AC/IC-4 | J21: EJW | L21: TAW
B22: Duty | C22: Efficiency % | D22: Duty | E22: Efficiency % | F22: Duty | G22: Efficiency % | H22: Duty | I22: Efficiency % | J22: Duty | K22: Efficiency % | L22: Duty | M22: Efficiency %
A23: 1 | B23: ='Constants and Properties'!$H$4/397.3*AVERAGE($B$13:$C$13)*1/24*1000000*'Constants and Properties'!$E$4*(B5-C5)/1000 -> 1838.8104 | C23: =B23/'Constants and Properties'!$B$21*100 -> 88.69885 | D23: ='Constants and Properties'!$H$4/397.3*AVERAGE($B$13:$C$13)*1/24*1000000*'Constants and Properties'!$E$4*(D5-E5)/1000 -> 1514.9041 | E23: =D23/'Constants and Properties'!$C$21*100 -> 105.44882 | F23: ='Constants and Properties'!$H$4/397.3*AVERAGE($B$13:$C$13)*1/24*1000000*'Constants and Properties'!$E$4*(F5-G5)/1000 -> 1742.3277 | G23: =F23/'Constants and Properties'!$D$21*100 -> 104.73621 | H23: ='Constants and Properties'!$H$4/397.3*AVERAGE($B$13:$C$13)*1/24*1000000*'Constants and Properties'!$E$4*(H5-I5)/1000 -> 1781.7979 | I23: =H23/'Constants and Properties'!$E$21*100 -> 99.452871 | J23: =62.4*AVERAGE(#REF!)*1/24*1000000*1*(K5-J5)/1000 -> #REF! | K23: =J23/'Constants and Properties'!$F$21*100 -> #REF! | M23: =L23/'Constants and Properties'!$G$21*100 -> 0
A24: 2 | B24: ='Constants and Properties'!$H$4/397.3*AVERAGE($B$14:$C$14)*1/24*1000000*'Constants and Properties'!$E$4*(B6-C6)/1000 -> 2110.4314 | C24: =B24/'Constants and Properties'!$B$21*100 -> 101.80106 | D24: ='Constants and Properties'!$H$4/397.3*AVERAGE($B$14:$C$14)*1/24*1000000*'Constants and Properties'!$E$4*(D6-E6)/1000 -> 1445.9379 | E24: =D24/'Constants and Properties'!$C$21*100 -> 100.64825 | F24: ='Constants and Properties'!$H$4/397.3*AVERAGE($B$14:$C$14)*1/24*1000000*'Constants and Properties'!$E$4*(F6-G6)/1000 -> 1672.7517 | G24: =F24/'Constants and Properties'!$D$21*100 -> 100.5538 | H24: ='Constants and Properties'!$H$4/397.3*AVERAGE($B$14:$C$14)*1/24*1000000*'Constants and Properties'!$E$4*(H6-I6)/1000 -> 1949.181 | I24: =H24/'Constants and Properties'!$E$21*100 -> 108.79553 | K24: =J24/'Constants and Properties'!$F$21*100 -> 0 | M24: =L24/'Constants and Properties'!$G$21*100 -> 0
A25: 3 | B25: ='Constants and Properties'!$H$4/397.3*AVERAGE($B$15:$C$15)*1/24*1000000*'Constants and Properties'!$E$4*(B7-C7)/1000 -> 2270.0397 | C25: =B25/'Constants and Properties'!$B$21*100 -> 109.50009 | D25: ='Constants and Properties'!$H$4/397.3*AVERAGE($B$15:$C$15)*1/24*1000000*'Constants and Properties'!$E$4*(D7-E7)/1000 -> 1349.0331 | E25: =D25/'Constants and Properties'!$C$21*100 -> 93.902939 | F25: ='Constants and Properties'!$H$4/397.3*AVERAGE($B$15:$C$15)*1/24*1000000*'Constants and Properties'!$E$4*(F7-G7)/1000 -> 1575.5375 | G25: =F25/'Constants and Properties'!$D$21*100 -> 94.709984 | H25: ='Constants and Properties'!$H$4/397.3*AVERAGE($B$15:$C$15)*1/24*1000000*'Constants and Properties'!$E$4*(H7-I7)/1000 -> 1643.8219 | I25: =H25/'Constants and Properties'!$E$21*100 -> 91.751598 | K25: =J25/'Constants and Properties'!$F$21*100 -> 0 | M25: =L25/'Constants and Properties'!$G$21*100 -> 0
A26: 4 | B26: ='Constants and Properties'!$H$4/397.3*AVERAGE($B$16:$C$16)*1/24*1000000*'Constants and Properties'!$E$4*(B8-C8)/1000 -> 731.45337 | C26: =B26/'Constants and Properties'!$B$22*100 -> 86.781626 | D26: ='Constants and Properties'!$H$4/397.3*AVERAGE($B$16:$C$16)*1/24*1000000*'Constants and Properties'!$E$4*(D8-E8)/1000 -> 888.80644 | E26: =D26/'Constants and Properties'!$C$22*100 -> 94.553189 | F26: ='Constants and Properties'!$H$4/397.3*AVERAGE($B$16:$C$16)*1/24*1000000*'Constants and Properties'!$E$4*(F8-G8)/1000 -> 1242.6124 | G26: =F26/'Constants and Properties'!$D$22*100 -> 97.883731 | H26: ='Constants and Properties'!$H$4/397.3*AVERAGE($B$16:$C$16)*1/24*1000000*'Constants and Properties'!$E$4*(H8-I8)/1000 -> 1077.6301 | I26: =H26/'Constants and Properties'!$E$22*100 -> 97.277698 | K26: =J26/'Constants and Properties'!$F$22*100 -> 0 | M26: =L26/'Constants and Properties'!$G$22*100 -> 0
A27: 5 | B27: ='Constants and Properties'!$H$4/397.3*AVERAGE($B$17:$C$17)*1/24*1000000*'Constants and Properties'!$E$4*(B9-C9)/1000 -> 954.2799 | C27: =B27/'Constants and Properties'!$B$22*100 -> 113.21837 | D27: ='Constants and Properties'!$H$4/397.3*AVERAGE($B$17:$C$17)*1/24*1000000*'Constants and Properties'!$E$4*(D9-E9)/1000 -> 991.20723 | E27: =D27/'Constants and Properties'!$C$22*100 -> 105.44681 | F27: ='Constants and Properties'!$H$4/397.3*AVERAGE($B$17:$C$17)*1/24*1000000*'Constants and Properties'!$E$4*(F9-G9)/1000 -> 1296.3436 | G27: =F27/'Constants and Properties'!$D$22*100 -> 102.11627 | H27: ='Constants and Properties'!$H$4/397.3*AVERAGE($B$17:$C$17)*1/24*1000000*'Constants and Properties'!$E$4*(H9-I9)/1000 -> 1137.9448 | I27: =H27/'Constants and Properties'!$E$22*100 -> 102.7223 | K27: =J27/'Constants and Properties'!$F$22*100 -> 0 | M27: =L27/'Constants and Properties'!$G$22*100 -> 0

Sheet FG coolers (3)
A1: HGF Flash Gas Cooler (3) Efficiency Calculator
A2: Temperatures (°F) | I2: Date of Assess
A3: Cooler # | B3: AC | D3: EJW | F3: TAW/CLO | I3: 45838
B4: T_in | C4: T_out | D4: T_in | E4: T_out | F4: T_in | G4: T_out
A5: 1 | B5: 189 | C5: 108 | D5: 190 | E5: 122
A6: 2
A7: 3
A9: Flows (MMCFD) | E9: T Setpoint (°F) & Louver Position (%)
A10: Cooler # | B10: Inlet Gas Today | C10: Total Flow Today | E10: Cooler # | F10: AC | I10: EJW | L10: TAW
A11: 1 | B11: 14.134 | F11: T Setpoint | G11: Louver | H11: Actual T | I11: T Setpoint | J11: Louver | K11: Actual T | L11: T Setpoint | M11: Louver | N11: Actual T
A12: 2 | E12: 1
A13: 3 | E13: 2
E14: 3
A16: Actual Duty (1000 BTU/hr)
A17: Cooler # | B17: AC | D17: EJW | F17: TAW
B18: Duty | C18: Efficiency % | D18: Duty | E18: Efficiency % | F18: Duty | G18: Efficiency %
A19: 1 | B19: ='Constants and Properties'!$H$4/397.3*AVERAGE($B$11:$C$11)*1/24*1000000*'Constants and Properties'!$E$4*(B5-C5)/1000 -> 1698.024 | C19: =B19/'Constants and Properties'!$B$35*100 -> 100 | E19: =D19/'Constants and Properties'!$F$21*100 -> 0 | G19: =F19/'Constants and Properties'!$G$21*100 -> 0
A20: 2 | B20: ='Constants and Properties'!$H$4/397.3*AVERAGE($B$12:$C$12)*1/24*1000000*'Constants and Properties'!$E$4*(B6-C6)/1000 -> #DIV/0! | C20: =B20/'Constants and Properties'!$E$21*100 -> #DIV/0! | E20: =D20/'Constants and Properties'!$F$21*100 -> 0 | G20: =F20/'Constants and Properties'!$G$21*100 -> 0
A21: 3 | B21: ='Constants and Properties'!$H$4/397.3*AVERAGE($B$13:$C$13)*1/24*1000000*'Constants and Properties'!$E$4*(B7-C7)/1000 -> #DIV/0! | C21: =B21/'Constants and Properties'!$E$21*100 -> #DIV/0! | E21: =D21/'Constants and Properties'!$F$21*100 -> 0 | G21: =F21/'Constants and Properties'!$G$21*100 -> 0

Sheet Refrig coolers (2)
A1: HGF Refrig Cooler (2) Efficiency Calculator
A2: Temperatures (°F) | I2: Date of Assess
A3: Cooler # | B3: EJW | D3: TAW | I3: 45838
B4: T_in | C4: T_out | D4: T_in | E4: T_out
A5: 1 | B5: 192 | C5: 121
A6: 2
A8: Flows (MMCFD) | D8: T Setpoint (°F) & Louver Position (%)
A9: Cooler # | B9: Inlet Gas Today | D9: Cooler # | E9: EJW | H9: TAW
A10: 1 | E10: T Setpoint | F10: Louver | G10: Actual T | H10: T Setpoint | I10: Louver | J10: Actual T
A11: 2 | D11: 1
D12: 2
A14: Actual Duty (1000 BTU/hr)
A15: Cooler # | B15: EJW | D15: TAW
B16: Duty | C16: Efficiency % | D16: Duty | E16: Efficiency %
A17: 1 | B17: ='Constants and Properties'!$H$4/397.3*AVERAGE($B$10:$C$10)*1/24*1000000*'Constants and Properties'!$E$4*(B5-C5)/1000 -> #DIV/0! | C17: =B17/'Constants and Properties'!$O$29*100 -> #DIV/0! | D17: =62.4*AVERAGE(#REF!)*1/24*1000000*1*(E5-D5)/1000 -> #REF! | E17: =D17/'Constants and Properties'!$F$21*100 -> #REF!
A18: 2 | B18: ='Constants and Properties'!$H$4/397.3*AVERAGE($B$11:$C$11)*1/24*1000000*'Constants and Properties'!$E$4*(B6-C6)/1000 -> #DIV/0! | C18: =B18/'Constants and Properties'!$E$21*100 -> #DIV/0! | E18: =D18/'Constants and Properties'!$F$21*100 -> 0

Sheet Constants and Properties
A1: Constants, Properties, Ratings, Pi Tags
A2: Gas Properties to Cooler
A3: Component | B3: mole % | C3: Cp at ~200 deg F | D3: xi*Cp,i | E3: Cp,mix [BTU/lb/°F] | F3: Molar mass (lb/lb-mol) | G3: xi*MM,i | H3: MM, mix (lb/lb-mol)
A4: Nitrogen | B4: 0.02249 | C4: 0.24 | D4: =B4*C4 -> 0.0053976 | E4: =SUM(D4:D17) -> 0.54375471 | F4: 28 | G4: ='Constants and Properties'!B4*F4 -> 0.62972 | H4: =SUM(G4:G17) -> 26.00881
A5: Methane | B5: 0.59446 | C5: 0.552 | D5: =B5*C5 -> 0.32814192 | F5: 16.05 | G5: ='Constants and Properties'!B5*F5 -> 9.541083
A6: Carbon Dioxde | B6: 0.00997 | C6: 0.219 | D6: =B6*C6 -> 0.00218343 | F6: 44 | G6: ='Constants and Properties'!B6*F6 -> 0.43868
A7: Ethane | B7: 0.19135 | C7: 0.584 | D7: =B7*C7 -> 0.1117484 | F7: 30 | G7: ='Constants and Properties'!B7*F7 -> 5.7405
A8: Propane | B8: 0.10028 | C8: 0.533 | D8: =B8*C8 -> 0.05344924 | F8: 44.1 | G8: ='Constants and Properties'!B8*F8 -> 4.422348
A9: i-Butane | B9: 0.01257 | C9: 0.535 | D9: =B9*C9 -> 0.00672495 | F9: 58.124 | G9: ='Constants and Properties'!B9*F9 -> 0.73061868
A10: n-Butane | B10: 0.03955 | C10: 0.518 | D10: =B10*C10 -> 0.0204869 | F10: 58.124 | G10: ='Constants and Properties'!B10*F10 -> 2.2988042
A11: i-Pentane | B11: 0.00915 | C11: 0.567 | D11: =B11*C11 -> 0.00518805 | F11: 72.151 | G11: ='Constants and Properties'!B11*F11 -> 0.66018165
A12: n-Pentane | B12: 0.01482 | C12: 0.522 | D12: =B12*C12 -> 0.00773604 | F12: 72.151 | G12: ='Constants and Properties'!B12*F12 -> 1.0692778
A13: n-Hexane | B13: 0.00437 | C13: 0.505 | D13: =B13*C13 -> 0.00220685 | F13: 86.18 | G13: ='Constants and Properties'!B13*F13 -> 0.3766066
A14: n-Heptane | B14: 0.00086 | C14: 0.497 | D14: =B14*C14 -> 0.00042742 | F14: 100 | G14: ='Constants and Properties'!B14*F14 -> 0.086
A15: n-Octane | B15: 0.00012 | C15: 0.492 | D15: =B15*C15 -> 5.904e-05 | F15: 114.232 | G15: ='Constants and Properties'!B15*F15 -> 0.01370784
A16: n-Nonane | B16: 1e-05 | C16: 0.487 | D16: =B16*C16 -> 4.87e-06 | F16: 128.26 | G16: ='Constants and Properties'!B16*F16 -> 0.0012826
A17: n-Decane | B17: 0 | C17: 0.483 | D17: =B17*C17 -> 0 | F17: 142 | G17: ='Constants and Properties'!B17*F17 -> 0
A19: Rated Duty (1000 BTU/hr) - Inlet Coolers
A20: Cooler type | B20: IC-1 | C20: IC-2 | D20: IC-3 | E20: AC | F20: EJW | G20: TAW/CLO
A21: H156-3-60 | B21: =AVERAGE('Inlet coolers (5)'!B23:B25) -> 2073.0938 | C21: =AVERAGE('Inlet coolers (5)'!D23:D25) -> 1436.6251 | D21: =AVERAGE('Inlet coolers (5)'!F23:F25) -> 1663.5389 | E21: =AVERAGE('Inlet coolers (5)'!H23:H25) -> 1791.6002 | F21: 2654 | G21: 4139.3
A22: H156-2-44 | B22: =AVERAGE('Inlet coolers (5)'!B26:B27) -> 842.86663 | C22: =AVERAGE('Inlet coolers (5)'!D26:D27) -> 940.00683 | D22: =AVERAGE('Inlet coolers (5)'!F26:F27) -> 1269.478 | E22: =AVERAGE('Inlet coolers (5)'!H26:H27) -> 1107.7874 | F22: 1305.8 | G22: 2101.6 | N22: Rated Duty (1000 BTU/hr) - Inlet Coolers - Spec Sheet
N23: Cooler type | O23: IC-1 | P23: IC-2 | Q23: IC-3 | R23: AC | S23: EJW | T23: TAW/CLO
A24: Relevant Pi Tags - Inlet Coolers | N24: H156-3-60 | O24: 3050 | P24: 2516 | Q24: 2958 | R24: 4103 | S24: 2654 | T24: 4139.3
A25: Cooler # | B25: IC-1 | D25: IC-2 | F25: IC-3 | H25: AC/IC-4 | J25: FIT | N25: H156-2-44 | O25: 1050.1 | P25: 1270.6 | Q25: 1561 | R25: 2433.5 | S25: 1305.8 | T25: 2101.6
B26: T_in | C26: T_out | D26: T_in | E26: T_out | F26: T_in | G26: T_out | H26: T_in | I26: T_out | J26: -
A27: 1 | B27: Compressor discharge temp (From Op Rounds) | C27: 752111 | D27: From Op Rounds | E27: 752112 | F27: From Op Rounds | G27: 752113 | H27: From Op Rounds | I27: 752114 | J27: 752101 | N27: Rated Duty (1000 BTU/hr) - FG Coolers - Spec Sheet
A28: 2 | B28: | | C28: 752211 | D28: | | E28: 752212 | F28: | | G28: 752213 | H28: | | I28: 752214 | J28: 752201 | N28: Cooler type | O28: AC | P28: EJW | Q28: TAW
A29: 3 | B29: | | C29: | | D29: | | E29: | | F29: | | G29: | | H29: | | I29: | | J29: | | N29: H120-1-16 | O29: 2431.6 | P29: 187.07 | Q29: 136.11
A30: 4 | B30: | | C30: | | D30: | | E30: | | F30: | | G30: | | H30: | | I30: | | J30: |
A31: 5 | B31: V | C31: V | D31: V | E31: V | F31: V | G31: V | H31: V | I31: V | J31: V | N31: Rated Duty (1000 BTU/hr) - Refrig Coolers - Spec Sheet
N32: Cooler type | O32: EJW | P32: TAW
A33: Rated Duty (1000 BTU/hr) - FG Coolers | N33: H90-1-12 | O33: 2971.3 | P33: 395.9
A34: Cooler type | B34: AC | C34: EJW | D34: TAW
A35: H120-1-16 | B35: 1698.024 | C35: 187.07 | D35: 136.11
A37: Relevant Pi Tags - FG Coolers
A38: Cooler # | B38: AC | D38: EJW | F38: TAW | H38: FIT
B39: T_in | C39: T_out | D39: T_in | E39: T_out | F39: T_in | G39: T_out | H39: -
A40: 1 | B40: Cylinder outlet temps (from operator rounds) | C40: 758113 | D40: From Op Rounds | E40: From Op Rounds | F40: ? | G40: ? | H40: 758111
A41: 2
A42: 3
...
